2021-02-19 16:15:54,225 ERROR: Exception on /tasks [GET] [in /Users/steve/Delphi Dropbox/Clients/TwinningProject/Code/TTP/venv/lib/python3.7/site-packages/flask/app.py: 1892]
Traceback (most recent call last):
  File "/Users/steve/Delphi Dropbox/Clients/TwinningProject/Code/TTP/venv/lib/python3.7/site-packages/flask/app.py", line 2447, in wsgi_app
    response = self.full_dispatch_request()
  File "/Users/steve/Delphi Dropbox/Clients/TwinningProject/Code/TTP/venv/lib/python3.7/site-packages/flask/app.py", line 1952, in full_dispatch_request
    rv = self.handle_user_exception(e)
  File "/Users/steve/Delphi Dropbox/Clients/TwinningProject/Code/TTP/venv/lib/python3.7/site-packages/flask/app.py", line 1821, in handle_user_exception
    reraise(exc_type, exc_value, tb)
  File "/Users/steve/Delphi Dropbox/Clients/TwinningProject/Code/TTP/venv/lib/python3.7/site-packages/flask/_compat.py", line 39, in reraise
    raise value
  File "/Users/steve/Delphi Dropbox/Clients/TwinningProject/Code/TTP/venv/lib/python3.7/site-packages/flask/app.py", line 1950, in full_dispatch_request
    rv = self.dispatch_request()
  File "/Users/steve/Delphi Dropbox/Clients/TwinningProject/Code/TTP/venv/lib/python3.7/site-packages/flask/app.py", line 1936, in dispatch_request
    return self.view_functions[rule.endpoint](**req.view_args)
  File "/Users/steve/Delphi Dropbox/Clients/TwinningProject/Code/TTP/venv/lib/python3.7/site-packages/flask_login/utils.py", line 272, in decorated_view
    return func(*args, **kwargs)
  File "/Users/steve/Delphi Dropbox/Clients/TwinningProject/Code/ttp/app/main/routes.py", line 835, in tasks
    taskdict['date'] = task.tk_duedate.format('DD/MM/YY')
AttributeError: 'datetime.datetime' object has no attribute 'format'
2021-02-19 16:15:56,572 ERROR: Exception on /tasks [GET] [in /Users/steve/Delphi Dropbox/Clients/TwinningProject/Code/TTP/venv/lib/python3.7/site-packages/flask/app.py: 1892]
Traceback (most recent call last):
  File "/Users/steve/Delphi Dropbox/Clients/TwinningProject/Code/TTP/venv/lib/python3.7/site-packages/flask/app.py", line 2447, in wsgi_app
    response = self.full_dispatch_request()
  File "/Users/steve/Delphi Dropbox/Clients/TwinningProject/Code/TTP/venv/lib/python3.7/site-packages/flask/app.py", line 1952, in full_dispatch_request
    rv = self.handle_user_exception(e)
  File "/Users/steve/Delphi Dropbox/Clients/TwinningProject/Code/TTP/venv/lib/python3.7/site-packages/flask/app.py", line 1821, in handle_user_exception
    reraise(exc_type, exc_value, tb)
  File "/Users/steve/Delphi Dropbox/Clients/TwinningProject/Code/TTP/venv/lib/python3.7/site-packages/flask/_compat.py", line 39, in reraise
    raise value
  File "/Users/steve/Delphi Dropbox/Clients/TwinningProject/Code/TTP/venv/lib/python3.7/site-packages/flask/app.py", line 1950, in full_dispatch_request
    rv = self.dispatch_request()
  File "/Users/steve/Delphi Dropbox/Clients/TwinningProject/Code/TTP/venv/lib/python3.7/site-packages/flask/app.py", line 1936, in dispatch_request
    return self.view_functions[rule.endpoint](**req.view_args)
  File "/Users/steve/Delphi Dropbox/Clients/TwinningProject/Code/TTP/venv/lib/python3.7/site-packages/flask_login/utils.py", line 272, in decorated_view
    return func(*args, **kwargs)
  File "/Users/steve/Delphi Dropbox/Clients/TwinningProject/Code/ttp/app/main/routes.py", line 835, in tasks
    taskdict['date'] = task.tk_duedate.format('DD/MM/YY')
AttributeError: 'datetime.datetime' object has no attribute 'format'
2021-02-19 16:16:45,532 INFO: The Twinning Project [in /Users/steve/Delphi Dropbox/Clients/TwinningProject/Code/ttp/app/__init__.py: 89]
2021-02-19 16:16:49,565 ERROR: Exception on /tasks [GET] [in /Users/steve/Delphi Dropbox/Clients/TwinningProject/Code/TTP/venv/lib/python3.7/site-packages/flask/app.py: 1892]
Traceback (most recent call last):
  File "/Users/steve/Delphi Dropbox/Clients/TwinningProject/Code/TTP/venv/lib/python3.7/site-packages/flask/app.py", line 2447, in wsgi_app
    response = self.full_dispatch_request()
  File "/Users/steve/Delphi Dropbox/Clients/TwinningProject/Code/TTP/venv/lib/python3.7/site-packages/flask/app.py", line 1952, in full_dispatch_request
    rv = self.handle_user_exception(e)
  File "/Users/steve/Delphi Dropbox/Clients/TwinningProject/Code/TTP/venv/lib/python3.7/site-packages/flask/app.py", line 1821, in handle_user_exception
    reraise(exc_type, exc_value, tb)
  File "/Users/steve/Delphi Dropbox/Clients/TwinningProject/Code/TTP/venv/lib/python3.7/site-packages/flask/_compat.py", line 39, in reraise
    raise value
  File "/Users/steve/Delphi Dropbox/Clients/TwinningProject/Code/TTP/venv/lib/python3.7/site-packages/flask/app.py", line 1950, in full_dispatch_request
    rv = self.dispatch_request()
  File "/Users/steve/Delphi Dropbox/Clients/TwinningProject/Code/TTP/venv/lib/python3.7/site-packages/flask/app.py", line 1936, in dispatch_request
    return self.view_functions[rule.endpoint](**req.view_args)
  File "/Users/steve/Delphi Dropbox/Clients/TwinningProject/Code/TTP/venv/lib/python3.7/site-packages/flask_login/utils.py", line 272, in decorated_view
    return func(*args, **kwargs)
  File "/Users/steve/Delphi Dropbox/Clients/TwinningProject/Code/ttp/app/main/routes.py", line 835, in tasks
    taskdict['date'] = moment(task.tk_duedate).format('DD/MM/YY')
NameError: name 'moment' is not defined
2021-02-19 16:16:51,071 ERROR: Exception on /tasks [GET] [in /Users/steve/Delphi Dropbox/Clients/TwinningProject/Code/TTP/venv/lib/python3.7/site-packages/flask/app.py: 1892]
Traceback (most recent call last):
  File "/Users/steve/Delphi Dropbox/Clients/TwinningProject/Code/TTP/venv/lib/python3.7/site-packages/flask/app.py", line 2447, in wsgi_app
    response = self.full_dispatch_request()
  File "/Users/steve/Delphi Dropbox/Clients/TwinningProject/Code/TTP/venv/lib/python3.7/site-packages/flask/app.py", line 1952, in full_dispatch_request
    rv = self.handle_user_exception(e)
  File "/Users/steve/Delphi Dropbox/Clients/TwinningProject/Code/TTP/venv/lib/python3.7/site-packages/flask/app.py", line 1821, in handle_user_exception
    reraise(exc_type, exc_value, tb)
  File "/Users/steve/Delphi Dropbox/Clients/TwinningProject/Code/TTP/venv/lib/python3.7/site-packages/flask/_compat.py", line 39, in reraise
    raise value
  File "/Users/steve/Delphi Dropbox/Clients/TwinningProject/Code/TTP/venv/lib/python3.7/site-packages/flask/app.py", line 1950, in full_dispatch_request
    rv = self.dispatch_request()
  File "/Users/steve/Delphi Dropbox/Clients/TwinningProject/Code/TTP/venv/lib/python3.7/site-packages/flask/app.py", line 1936, in dispatch_request
    return self.view_functions[rule.endpoint](**req.view_args)
  File "/Users/steve/Delphi Dropbox/Clients/TwinningProject/Code/TTP/venv/lib/python3.7/site-packages/flask_login/utils.py", line 272, in decorated_view
    return func(*args, **kwargs)
  File "/Users/steve/Delphi Dropbox/Clients/TwinningProject/Code/ttp/app/main/routes.py", line 835, in tasks
    taskdict['date'] = moment(task.tk_duedate).format('DD/MM/YY')
NameError: name 'moment' is not defined
2021-02-19 16:17:25,995 INFO: The Twinning Project [in /Users/steve/Delphi Dropbox/Clients/TwinningProject/Code/ttp/app/__init__.py: 89]
2021-02-19 16:17:28,004 ERROR: Exception on /tasks [GET] [in /Users/steve/Delphi Dropbox/Clients/TwinningProject/Code/TTP/venv/lib/python3.7/site-packages/flask/app.py: 1892]
Traceback (most recent call last):
  File "/Users/steve/Delphi Dropbox/Clients/TwinningProject/Code/TTP/venv/lib/python3.7/site-packages/flask/app.py", line 2447, in wsgi_app
    response = self.full_dispatch_request()
  File "/Users/steve/Delphi Dropbox/Clients/TwinningProject/Code/TTP/venv/lib/python3.7/site-packages/flask/app.py", line 1952, in full_dispatch_request
    rv = self.handle_user_exception(e)
  File "/Users/steve/Delphi Dropbox/Clients/TwinningProject/Code/TTP/venv/lib/python3.7/site-packages/flask/app.py", line 1821, in handle_user_exception
    reraise(exc_type, exc_value, tb)
  File "/Users/steve/Delphi Dropbox/Clients/TwinningProject/Code/TTP/venv/lib/python3.7/site-packages/flask/_compat.py", line 39, in reraise
    raise value
  File "/Users/steve/Delphi Dropbox/Clients/TwinningProject/Code/TTP/venv/lib/python3.7/site-packages/flask/app.py", line 1950, in full_dispatch_request
    rv = self.dispatch_request()
  File "/Users/steve/Delphi Dropbox/Clients/TwinningProject/Code/TTP/venv/lib/python3.7/site-packages/flask/app.py", line 1936, in dispatch_request
    return self.view_functions[rule.endpoint](**req.view_args)
  File "/Users/steve/Delphi Dropbox/Clients/TwinningProject/Code/TTP/venv/lib/python3.7/site-packages/flask_login/utils.py", line 272, in decorated_view
    return func(*args, **kwargs)
  File "/Users/steve/Delphi Dropbox/Clients/TwinningProject/Code/ttp/app/main/routes.py", line 835, in tasks
    taskdict['date'] = task.tk_duedate.type()
AttributeError: 'datetime.datetime' object has no attribute 'type'
2021-02-19 16:17:54,955 INFO: The Twinning Project [in /Users/steve/Delphi Dropbox/Clients/TwinningProject/Code/ttp/app/__init__.py: 89]
2021-02-19 16:24:53,253 INFO: The Twinning Project [in /Users/steve/Delphi Dropbox/Clients/TwinningProject/Code/ttp/app/__init__.py: 89]
