2020-05-28 11:58:18,998 INFO: The Twinning Project [in /Users/steve/Delphi Dropbox/Clients/TwinningProject/Code/TTP/app/__init__.py: 76]
2020-05-28 12:01:17,294 INFO: The Twinning Project [in /Users/steve/Delphi Dropbox/Clients/TwinningProject/Code/TTP/app/__init__.py: 76]
2020-05-28 12:04:49,295 INFO: The Twinning Project [in /Users/steve/Delphi Dropbox/Clients/TwinningProject/Code/TTP/app/__init__.py: 76]
2020-05-28 12:04:51,699 ERROR: Exception on /index [GET] [in /Users/steve/Delphi Dropbox/Clients/TwinningProject/Code/TTP/venv/lib/python3.7/site-packages/flask/app.py: 1892]
Traceback (most recent call last):
  File "/Users/steve/Delphi Dropbox/Clients/TwinningProject/Code/TTP/venv/lib/python3.7/site-packages/flask/app.py", line 2447, in wsgi_app
    response = self.full_dispatch_request()
  File "/Users/steve/Delphi Dropbox/Clients/TwinningProject/Code/TTP/venv/lib/python3.7/site-packages/flask/app.py", line 1952, in full_dispatch_request
    rv = self.handle_user_exception(e)
  File "/Users/steve/Delphi Dropbox/Clients/TwinningProject/Code/TTP/venv/lib/python3.7/site-packages/flask/app.py", line 1821, in handle_user_exception
    reraise(exc_type, exc_value, tb)
  File "/Users/steve/Delphi Dropbox/Clients/TwinningProject/Code/TTP/venv/lib/python3.7/site-packages/flask/_compat.py", line 39, in reraise
    raise value
  File "/Users/steve/Delphi Dropbox/Clients/TwinningProject/Code/TTP/venv/lib/python3.7/site-packages/flask/app.py", line 1950, in full_dispatch_request
    rv = self.dispatch_request()
  File "/Users/steve/Delphi Dropbox/Clients/TwinningProject/Code/TTP/venv/lib/python3.7/site-packages/flask/app.py", line 1936, in dispatch_request
    return self.view_functions[rule.endpoint](**req.view_args)
  File "/Users/steve/Delphi Dropbox/Clients/TwinningProject/Code/TTP/app/main/routes.py", line 18, in index
    today = datetime.date()
TypeError: descriptor 'date' of 'datetime.datetime' object needs an argument
2020-05-28 12:07:04,576 INFO: The Twinning Project [in /Users/steve/Delphi Dropbox/Clients/TwinningProject/Code/TTP/app/__init__.py: 76]
2020-05-28 12:07:52,265 INFO: The Twinning Project [in /Users/steve/Delphi Dropbox/Clients/TwinningProject/Code/TTP/app/__init__.py: 76]
2020-05-28 12:07:54,652 ERROR: Exception on /index [GET] [in /Users/steve/Delphi Dropbox/Clients/TwinningProject/Code/TTP/venv/lib/python3.7/site-packages/flask/app.py: 1892]
Traceback (most recent call last):
  File "/Users/steve/Delphi Dropbox/Clients/TwinningProject/Code/TTP/venv/lib/python3.7/site-packages/flask/app.py", line 2447, in wsgi_app
    response = self.full_dispatch_request()
  File "/Users/steve/Delphi Dropbox/Clients/TwinningProject/Code/TTP/venv/lib/python3.7/site-packages/flask/app.py", line 1952, in full_dispatch_request
    rv = self.handle_user_exception(e)
  File "/Users/steve/Delphi Dropbox/Clients/TwinningProject/Code/TTP/venv/lib/python3.7/site-packages/flask/app.py", line 1821, in handle_user_exception
    reraise(exc_type, exc_value, tb)
  File "/Users/steve/Delphi Dropbox/Clients/TwinningProject/Code/TTP/venv/lib/python3.7/site-packages/flask/_compat.py", line 39, in reraise
    raise value
  File "/Users/steve/Delphi Dropbox/Clients/TwinningProject/Code/TTP/venv/lib/python3.7/site-packages/flask/app.py", line 1950, in full_dispatch_request
    rv = self.dispatch_request()
  File "/Users/steve/Delphi Dropbox/Clients/TwinningProject/Code/TTP/venv/lib/python3.7/site-packages/flask/app.py", line 1936, in dispatch_request
    return self.view_functions[rule.endpoint](**req.view_args)
  File "/Users/steve/Delphi Dropbox/Clients/TwinningProject/Code/TTP/app/main/routes.py", line 19, in index
    flash(date(today))
TypeError: an integer is required (got type builtin_function_or_method)
2020-05-28 12:09:24,386 INFO: The Twinning Project [in /Users/steve/Delphi Dropbox/Clients/TwinningProject/Code/TTP/app/__init__.py: 76]
2020-05-28 12:09:26,147 ERROR: Exception on /index [GET] [in /Users/steve/Delphi Dropbox/Clients/TwinningProject/Code/TTP/venv/lib/python3.7/site-packages/flask/app.py: 1892]
Traceback (most recent call last):
  File "/Users/steve/Delphi Dropbox/Clients/TwinningProject/Code/TTP/venv/lib/python3.7/site-packages/flask/app.py", line 2447, in wsgi_app
    response = self.full_dispatch_request()
  File "/Users/steve/Delphi Dropbox/Clients/TwinningProject/Code/TTP/venv/lib/python3.7/site-packages/flask/app.py", line 1952, in full_dispatch_request
    rv = self.handle_user_exception(e)
  File "/Users/steve/Delphi Dropbox/Clients/TwinningProject/Code/TTP/venv/lib/python3.7/site-packages/flask/app.py", line 1821, in handle_user_exception
    reraise(exc_type, exc_value, tb)
  File "/Users/steve/Delphi Dropbox/Clients/TwinningProject/Code/TTP/venv/lib/python3.7/site-packages/flask/_compat.py", line 39, in reraise
    raise value
  File "/Users/steve/Delphi Dropbox/Clients/TwinningProject/Code/TTP/venv/lib/python3.7/site-packages/flask/app.py", line 1950, in full_dispatch_request
    rv = self.dispatch_request()
  File "/Users/steve/Delphi Dropbox/Clients/TwinningProject/Code/TTP/venv/lib/python3.7/site-packages/flask/app.py", line 1936, in dispatch_request
    return self.view_functions[rule.endpoint](**req.view_args)
  File "/Users/steve/Delphi Dropbox/Clients/TwinningProject/Code/TTP/app/main/routes.py", line 18, in index
    today = datetime.utcnow.date
AttributeError: 'builtin_function_or_method' object has no attribute 'date'
2020-05-28 12:09:48,662 INFO: The Twinning Project [in /Users/steve/Delphi Dropbox/Clients/TwinningProject/Code/TTP/app/__init__.py: 76]
2020-05-28 12:09:52,380 ERROR: Exception on /index [GET] [in /Users/steve/Delphi Dropbox/Clients/TwinningProject/Code/TTP/venv/lib/python3.7/site-packages/flask/app.py: 1892]
Traceback (most recent call last):
  File "/Users/steve/Delphi Dropbox/Clients/TwinningProject/Code/TTP/venv/lib/python3.7/site-packages/flask/app.py", line 2447, in wsgi_app
    response = self.full_dispatch_request()
  File "/Users/steve/Delphi Dropbox/Clients/TwinningProject/Code/TTP/venv/lib/python3.7/site-packages/flask/app.py", line 1952, in full_dispatch_request
    rv = self.handle_user_exception(e)
  File "/Users/steve/Delphi Dropbox/Clients/TwinningProject/Code/TTP/venv/lib/python3.7/site-packages/flask/app.py", line 1821, in handle_user_exception
    reraise(exc_type, exc_value, tb)
  File "/Users/steve/Delphi Dropbox/Clients/TwinningProject/Code/TTP/venv/lib/python3.7/site-packages/flask/_compat.py", line 39, in reraise
    raise value
  File "/Users/steve/Delphi Dropbox/Clients/TwinningProject/Code/TTP/venv/lib/python3.7/site-packages/flask/app.py", line 1950, in full_dispatch_request
    rv = self.dispatch_request()
  File "/Users/steve/Delphi Dropbox/Clients/TwinningProject/Code/TTP/venv/lib/python3.7/site-packages/flask/app.py", line 1936, in dispatch_request
    return self.view_functions[rule.endpoint](**req.view_args)
  File "/Users/steve/Delphi Dropbox/Clients/TwinningProject/Code/TTP/app/main/routes.py", line 18, in index
    today = datetime.utcnow.date()
AttributeError: 'builtin_function_or_method' object has no attribute 'date'
2020-05-28 12:10:36,867 INFO: The Twinning Project [in /Users/steve/Delphi Dropbox/Clients/TwinningProject/Code/TTP/app/__init__.py: 76]
2020-05-28 12:10:40,346 ERROR: Exception on /index [GET] [in /Users/steve/Delphi Dropbox/Clients/TwinningProject/Code/TTP/venv/lib/python3.7/site-packages/flask/app.py: 1892]
Traceback (most recent call last):
  File "/Users/steve/Delphi Dropbox/Clients/TwinningProject/Code/TTP/venv/lib/python3.7/site-packages/flask/app.py", line 2447, in wsgi_app
    response = self.full_dispatch_request()
  File "/Users/steve/Delphi Dropbox/Clients/TwinningProject/Code/TTP/venv/lib/python3.7/site-packages/flask/app.py", line 1952, in full_dispatch_request
    rv = self.handle_user_exception(e)
  File "/Users/steve/Delphi Dropbox/Clients/TwinningProject/Code/TTP/venv/lib/python3.7/site-packages/flask/app.py", line 1821, in handle_user_exception
    reraise(exc_type, exc_value, tb)
  File "/Users/steve/Delphi Dropbox/Clients/TwinningProject/Code/TTP/venv/lib/python3.7/site-packages/flask/_compat.py", line 39, in reraise
    raise value
  File "/Users/steve/Delphi Dropbox/Clients/TwinningProject/Code/TTP/venv/lib/python3.7/site-packages/flask/app.py", line 1950, in full_dispatch_request
    rv = self.dispatch_request()
  File "/Users/steve/Delphi Dropbox/Clients/TwinningProject/Code/TTP/venv/lib/python3.7/site-packages/flask/app.py", line 1936, in dispatch_request
    return self.view_functions[rule.endpoint](**req.view_args)
  File "/Users/steve/Delphi Dropbox/Clients/TwinningProject/Code/TTP/app/main/routes.py", line 18, in index
    today = date.utcnow
AttributeError: type object 'datetime.date' has no attribute 'utcnow'
