2020-08-17 17:09:52,527 ERROR: Exception on /static/js/plugins/bootstrap-notify.js [GET] [in /opt/anaconda3/lib/python3.7/site-packages/flask/app.py: 1892]
Traceback (most recent call last):
  File "/opt/anaconda3/lib/python3.7/site-packages/flask/app.py", line 2447, in wsgi_app
    response = self.full_dispatch_request()
  File "/opt/anaconda3/lib/python3.7/site-packages/flask/app.py", line 1952, in full_dispatch_request
    rv = self.handle_user_exception(e)
  File "/opt/anaconda3/lib/python3.7/site-packages/flask/app.py", line 1821, in handle_user_exception
    reraise(exc_type, exc_value, tb)
  File "/opt/anaconda3/lib/python3.7/site-packages/flask/_compat.py", line 39, in reraise
    raise value
  File "/opt/anaconda3/lib/python3.7/site-packages/flask/app.py", line 1948, in full_dispatch_request
    rv = self.preprocess_request()
  File "/opt/anaconda3/lib/python3.7/site-packages/flask/app.py", line 2242, in preprocess_request
    rv = func()
  File "/Users/steve/Delphi Dropbox/Clients/TwinningProject/Code/TTP/app/main/routes.py", line 11, in before_request
    if current_user.is_authenticated:
  File "/opt/anaconda3/lib/python3.7/site-packages/werkzeug/local.py", line 347, in __getattr__
    return getattr(self._get_current_object(), name)
  File "/opt/anaconda3/lib/python3.7/site-packages/werkzeug/local.py", line 306, in _get_current_object
    return self.__local()
  File "/opt/anaconda3/lib/python3.7/site-packages/flask_login/utils.py", line 26, in <lambda>
    current_user = LocalProxy(lambda: _get_user())
  File "/opt/anaconda3/lib/python3.7/site-packages/flask_login/utils.py", line 346, in _get_user
    current_app.login_manager._load_user()
  File "/opt/anaconda3/lib/python3.7/site-packages/flask_login/login_manager.py", line 318, in _load_user
    user = self._user_callback(user_id)
  File "/Users/steve/Delphi Dropbox/Clients/TwinningProject/Code/TTP/app/models.py", line 45, in load_user
    return User.query.get(int(id))
  File "/opt/anaconda3/lib/python3.7/site-packages/flask_sqlalchemy/__init__.py", line 517, in __get__
    mapper = orm.class_mapper(type)
  File "/opt/anaconda3/lib/python3.7/site-packages/sqlalchemy/orm/base.py", line 451, in class_mapper
    mapper = _inspect_mapped_class(class_, configure=configure)
  File "/opt/anaconda3/lib/python3.7/site-packages/sqlalchemy/orm/base.py", line 430, in _inspect_mapped_class
    mapper._configure_all()
  File "/opt/anaconda3/lib/python3.7/site-packages/sqlalchemy/orm/mapper.py", line 1337, in _configure_all
    configure_mappers()
  File "/opt/anaconda3/lib/python3.7/site-packages/sqlalchemy/orm/mapper.py", line 3251, in configure_mappers
    raise e
sqlalchemy.exc.InvalidRequestError: One or more mappers failed to initialize - can't proceed with initialization of other mappers. Triggering mapper: 'mapped class Club->club'. Original exception was: Could not determine join condition between parent/child tables on relationship Club.clb_twinned_id - there are no foreign keys linking these tables.  Ensure that referencing columns are associated with a ForeignKey or ForeignKeyConstraint, or specify a 'primaryjoin' expression.
2020-08-17 17:09:52,529 ERROR: Exception on /static/js/material-dashboard.js [GET] [in /opt/anaconda3/lib/python3.7/site-packages/flask/app.py: 1892]
Traceback (most recent call last):
  File "/opt/anaconda3/lib/python3.7/site-packages/flask/app.py", line 2447, in wsgi_app
    response = self.full_dispatch_request()
  File "/opt/anaconda3/lib/python3.7/site-packages/flask/app.py", line 1952, in full_dispatch_request
    rv = self.handle_user_exception(e)
  File "/opt/anaconda3/lib/python3.7/site-packages/flask/app.py", line 1821, in handle_user_exception
    reraise(exc_type, exc_value, tb)
  File "/opt/anaconda3/lib/python3.7/site-packages/flask/_compat.py", line 39, in reraise
    raise value
  File "/opt/anaconda3/lib/python3.7/site-packages/flask/app.py", line 1948, in full_dispatch_request
    rv = self.preprocess_request()
  File "/opt/anaconda3/lib/python3.7/site-packages/flask/app.py", line 2242, in preprocess_request
    rv = func()
  File "/Users/steve/Delphi Dropbox/Clients/TwinningProject/Code/TTP/app/main/routes.py", line 11, in before_request
    if current_user.is_authenticated:
  File "/opt/anaconda3/lib/python3.7/site-packages/werkzeug/local.py", line 347, in __getattr__
    return getattr(self._get_current_object(), name)
  File "/opt/anaconda3/lib/python3.7/site-packages/werkzeug/local.py", line 306, in _get_current_object
    return self.__local()
  File "/opt/anaconda3/lib/python3.7/site-packages/flask_login/utils.py", line 26, in <lambda>
    current_user = LocalProxy(lambda: _get_user())
  File "/opt/anaconda3/lib/python3.7/site-packages/flask_login/utils.py", line 346, in _get_user
    current_app.login_manager._load_user()
  File "/opt/anaconda3/lib/python3.7/site-packages/flask_login/login_manager.py", line 318, in _load_user
    user = self._user_callback(user_id)
  File "/Users/steve/Delphi Dropbox/Clients/TwinningProject/Code/TTP/app/models.py", line 45, in load_user
    return User.query.get(int(id))
  File "/opt/anaconda3/lib/python3.7/site-packages/flask_sqlalchemy/__init__.py", line 517, in __get__
    mapper = orm.class_mapper(type)
  File "/opt/anaconda3/lib/python3.7/site-packages/sqlalchemy/orm/base.py", line 451, in class_mapper
    mapper = _inspect_mapped_class(class_, configure=configure)
  File "/opt/anaconda3/lib/python3.7/site-packages/sqlalchemy/orm/base.py", line 430, in _inspect_mapped_class
    mapper._configure_all()
  File "/opt/anaconda3/lib/python3.7/site-packages/sqlalchemy/orm/mapper.py", line 1337, in _configure_all
    configure_mappers()
  File "/opt/anaconda3/lib/python3.7/site-packages/sqlalchemy/orm/mapper.py", line 3251, in configure_mappers
    raise e
sqlalchemy.exc.InvalidRequestError: One or more mappers failed to initialize - can't proceed with initialization of other mappers. Triggering mapper: 'mapped class Club->club'. Original exception was: Could not determine join condition between parent/child tables on relationship Club.clb_twinned_id - there are no foreign keys linking these tables.  Ensure that referencing columns are associated with a ForeignKey or ForeignKeyConstraint, or specify a 'primaryjoin' expression.
2020-08-17 17:09:52,539 ERROR: Exception on /static/js/demo.js [GET] [in /opt/anaconda3/lib/python3.7/site-packages/flask/app.py: 1892]
Traceback (most recent call last):
  File "/opt/anaconda3/lib/python3.7/site-packages/flask/app.py", line 2447, in wsgi_app
    response = self.full_dispatch_request()
  File "/opt/anaconda3/lib/python3.7/site-packages/flask/app.py", line 1952, in full_dispatch_request
    rv = self.handle_user_exception(e)
  File "/opt/anaconda3/lib/python3.7/site-packages/flask/app.py", line 1821, in handle_user_exception
    reraise(exc_type, exc_value, tb)
  File "/opt/anaconda3/lib/python3.7/site-packages/flask/_compat.py", line 39, in reraise
    raise value
  File "/opt/anaconda3/lib/python3.7/site-packages/flask/app.py", line 1948, in full_dispatch_request
    rv = self.preprocess_request()
  File "/opt/anaconda3/lib/python3.7/site-packages/flask/app.py", line 2242, in preprocess_request
    rv = func()
  File "/Users/steve/Delphi Dropbox/Clients/TwinningProject/Code/TTP/app/main/routes.py", line 11, in before_request
    if current_user.is_authenticated:
  File "/opt/anaconda3/lib/python3.7/site-packages/werkzeug/local.py", line 347, in __getattr__
    return getattr(self._get_current_object(), name)
  File "/opt/anaconda3/lib/python3.7/site-packages/werkzeug/local.py", line 306, in _get_current_object
    return self.__local()
  File "/opt/anaconda3/lib/python3.7/site-packages/flask_login/utils.py", line 26, in <lambda>
    current_user = LocalProxy(lambda: _get_user())
  File "/opt/anaconda3/lib/python3.7/site-packages/flask_login/utils.py", line 346, in _get_user
    current_app.login_manager._load_user()
  File "/opt/anaconda3/lib/python3.7/site-packages/flask_login/login_manager.py", line 318, in _load_user
    user = self._user_callback(user_id)
  File "/Users/steve/Delphi Dropbox/Clients/TwinningProject/Code/TTP/app/models.py", line 45, in load_user
    return User.query.get(int(id))
  File "/opt/anaconda3/lib/python3.7/site-packages/flask_sqlalchemy/__init__.py", line 517, in __get__
    mapper = orm.class_mapper(type)
  File "/opt/anaconda3/lib/python3.7/site-packages/sqlalchemy/orm/base.py", line 451, in class_mapper
    mapper = _inspect_mapped_class(class_, configure=configure)
  File "/opt/anaconda3/lib/python3.7/site-packages/sqlalchemy/orm/base.py", line 430, in _inspect_mapped_class
    mapper._configure_all()
  File "/opt/anaconda3/lib/python3.7/site-packages/sqlalchemy/orm/mapper.py", line 1337, in _configure_all
    configure_mappers()
  File "/opt/anaconda3/lib/python3.7/site-packages/sqlalchemy/orm/mapper.py", line 3251, in configure_mappers
    raise e
sqlalchemy.exc.InvalidRequestError: One or more mappers failed to initialize - can't proceed with initialization of other mappers. Triggering mapper: 'mapped class Club->club'. Original exception was: Could not determine join condition between parent/child tables on relationship Club.clb_twinned_id - there are no foreign keys linking these tables.  Ensure that referencing columns are associated with a ForeignKey or ForeignKeyConstraint, or specify a 'primaryjoin' expression.
2020-08-17 17:13:57,802 INFO: The Twinning Project [in /Users/steve/Delphi Dropbox/Clients/TwinningProject/Code/TTP/app/__init__.py: 81]
2020-08-17 17:14:04,906 INFO: The Twinning Project [in /Users/steve/Delphi Dropbox/Clients/TwinningProject/Code/TTP/app/__init__.py: 81]
2020-08-17 17:14:11,526 INFO: The Twinning Project [in /Users/steve/Delphi Dropbox/Clients/TwinningProject/Code/TTP/app/__init__.py: 81]
