2020-07-27 15:55:16,440 ERROR: Exception on /newkit/9 [POST] [in /opt/anaconda3/lib/python3.7/site-packages/flask/app.py: 1892]
Traceback (most recent call last):
  File "/opt/anaconda3/lib/python3.7/site-packages/sqlalchemy/engine/base.py", line 1248, in _execute_context
    cursor, statement, parameters, context
  File "/opt/anaconda3/lib/python3.7/site-packages/sqlalchemy/engine/default.py", line 590, in do_execute
    cursor.execute(statement, parameters)
sqlite3.OperationalError: table kit has no column named kit_numSmall

The above exception was the direct cause of the following exception:

Traceback (most recent call last):
  File "/opt/anaconda3/lib/python3.7/site-packages/flask/app.py", line 2447, in wsgi_app
    response = self.full_dispatch_request()
  File "/opt/anaconda3/lib/python3.7/site-packages/flask/app.py", line 1952, in full_dispatch_request
    rv = self.handle_user_exception(e)
  File "/opt/anaconda3/lib/python3.7/site-packages/flask/app.py", line 1821, in handle_user_exception
    reraise(exc_type, exc_value, tb)
  File "/opt/anaconda3/lib/python3.7/site-packages/flask/_compat.py", line 39, in reraise
    raise value
  File "/opt/anaconda3/lib/python3.7/site-packages/flask/app.py", line 1950, in full_dispatch_request
    rv = self.dispatch_request()
  File "/opt/anaconda3/lib/python3.7/site-packages/flask/app.py", line 1936, in dispatch_request
    return self.view_functions[rule.endpoint](**req.view_args)
  File "/opt/anaconda3/lib/python3.7/site-packages/flask_login/utils.py", line 272, in decorated_view
    return func(*args, **kwargs)
  File "/Users/steve/Delphi Dropbox/Clients/TwinningProject/Code/TTP/app/main/routes.py", line 386, in newkit
    db.session.commit()
  File "/opt/anaconda3/lib/python3.7/site-packages/sqlalchemy/orm/scoping.py", line 162, in do
    return getattr(self.registry(), name)(*args, **kwargs)
  File "/opt/anaconda3/lib/python3.7/site-packages/sqlalchemy/orm/session.py", line 1036, in commit
    self.transaction.commit()
  File "/opt/anaconda3/lib/python3.7/site-packages/sqlalchemy/orm/session.py", line 503, in commit
    self._prepare_impl()
  File "/opt/anaconda3/lib/python3.7/site-packages/sqlalchemy/orm/session.py", line 482, in _prepare_impl
    self.session.flush()
  File "/opt/anaconda3/lib/python3.7/site-packages/sqlalchemy/orm/session.py", line 2496, in flush
    self._flush(objects)
  File "/opt/anaconda3/lib/python3.7/site-packages/sqlalchemy/orm/session.py", line 2637, in _flush
    transaction.rollback(_capture_exception=True)
  File "/opt/anaconda3/lib/python3.7/site-packages/sqlalchemy/util/langhelpers.py", line 69, in __exit__
    exc_value, with_traceback=exc_tb,
  File "/opt/anaconda3/lib/python3.7/site-packages/sqlalchemy/util/compat.py", line 178, in raise_
    raise exception
  File "/opt/anaconda3/lib/python3.7/site-packages/sqlalchemy/orm/session.py", line 2597, in _flush
    flush_context.execute()
  File "/opt/anaconda3/lib/python3.7/site-packages/sqlalchemy/orm/unitofwork.py", line 422, in execute
    rec.execute(self)
  File "/opt/anaconda3/lib/python3.7/site-packages/sqlalchemy/orm/unitofwork.py", line 589, in execute
    uow,
  File "/opt/anaconda3/lib/python3.7/site-packages/sqlalchemy/orm/persistence.py", line 245, in save_obj
    insert,
  File "/opt/anaconda3/lib/python3.7/site-packages/sqlalchemy/orm/persistence.py", line 1136, in _emit_insert_statements
    statement, params
  File "/opt/anaconda3/lib/python3.7/site-packages/sqlalchemy/engine/base.py", line 984, in execute
    return meth(self, multiparams, params)
  File "/opt/anaconda3/lib/python3.7/site-packages/sqlalchemy/sql/elements.py", line 293, in _execute_on_connection
    return connection._execute_clauseelement(self, multiparams, params)
  File "/opt/anaconda3/lib/python3.7/site-packages/sqlalchemy/engine/base.py", line 1103, in _execute_clauseelement
    distilled_params,
  File "/opt/anaconda3/lib/python3.7/site-packages/sqlalchemy/engine/base.py", line 1288, in _execute_context
    e, statement, parameters, cursor, context
  File "/opt/anaconda3/lib/python3.7/site-packages/sqlalchemy/engine/base.py", line 1482, in _handle_dbapi_exception
    sqlalchemy_exception, with_traceback=exc_info[2], from_=e
  File "/opt/anaconda3/lib/python3.7/site-packages/sqlalchemy/util/compat.py", line 178, in raise_
    raise exception
  File "/opt/anaconda3/lib/python3.7/site-packages/sqlalchemy/engine/base.py", line 1248, in _execute_context
    cursor, statement, parameters, context
  File "/opt/anaconda3/lib/python3.7/site-packages/sqlalchemy/engine/default.py", line 590, in do_execute
    cursor.execute(statement, parameters)
sqlalchemy.exc.OperationalError: (sqlite3.OperationalError) table kit has no column named kit_numSmall
[SQL: INSERT INTO kit (kit_cohortid, "kit_numSmall", "kit_numMedium", "kit_numLarge", kit_date) VALUES (?, ?, ?, ?, ?)]
[parameters: ('9', 12, 4, 6, '2020-07-27 00:00:00.000000')]
(Background on this error at: http://sqlalche.me/e/e3q8)
2020-08-04 11:42:00,862 INFO: The Twinning Project [in /Users/steve/Delphi Dropbox/Clients/TwinningProject/Code/TTP/app/__init__.py: 81]
2020-08-04 12:10:15,746 INFO: The Twinning Project [in /Users/steve/Delphi Dropbox/Clients/TwinningProject/Code/TTP/app/__init__.py: 81]
2020-08-04 12:14:20,052 INFO: The Twinning Project [in /Users/steve/Delphi Dropbox/Clients/TwinningProject/Code/TTP/app/__init__.py: 81]
2020-08-04 12:19:17,901 INFO: The Twinning Project [in /Users/steve/Delphi Dropbox/Clients/TwinningProject/Code/TTP/app/__init__.py: 81]
2020-08-04 12:27:35,578 INFO: The Twinning Project [in /Users/steve/Delphi Dropbox/Clients/TwinningProject/Code/TTP/app/__init__.py: 81]
