2021-11-17 11:43:20,747 ERROR: Exception on /assignkit/11 [POST] [in /Library/Frameworks/Python.framework/Versions/3.7/lib/python3.7/site-packages/flask/app.py: 1892]
Traceback (most recent call last):
  File "/Library/Frameworks/Python.framework/Versions/3.7/lib/python3.7/site-packages/sqlalchemy/engine/base.py", line 1175, in _execute_context
    context = constructor(dialect, self, conn, *args)
  File "/Library/Frameworks/Python.framework/Versions/3.7/lib/python3.7/site-packages/sqlalchemy/engine/default.py", line 836, in _init_compiled
    param.append(processors[key](compiled_params[key]))
  File "/Library/Frameworks/Python.framework/Versions/3.7/lib/python3.7/site-packages/sqlalchemy/dialects/sqlite/base.py", line 768, in process
    "SQLite DateTime type only accepts Python "
TypeError: SQLite DateTime type only accepts Python datetime and date objects as input.

The above exception was the direct cause of the following exception:

Traceback (most recent call last):
  File "/Library/Frameworks/Python.framework/Versions/3.7/lib/python3.7/site-packages/flask/app.py", line 2447, in wsgi_app
    response = self.full_dispatch_request()
  File "/Library/Frameworks/Python.framework/Versions/3.7/lib/python3.7/site-packages/flask/app.py", line 1952, in full_dispatch_request
    rv = self.handle_user_exception(e)
  File "/Library/Frameworks/Python.framework/Versions/3.7/lib/python3.7/site-packages/flask/app.py", line 1821, in handle_user_exception
    reraise(exc_type, exc_value, tb)
  File "/Library/Frameworks/Python.framework/Versions/3.7/lib/python3.7/site-packages/flask/_compat.py", line 39, in reraise
    raise value
  File "/Library/Frameworks/Python.framework/Versions/3.7/lib/python3.7/site-packages/flask/app.py", line 1950, in full_dispatch_request
    rv = self.dispatch_request()
  File "/Library/Frameworks/Python.framework/Versions/3.7/lib/python3.7/site-packages/flask/app.py", line 1936, in dispatch_request
    return self.view_functions[rule.endpoint](**req.view_args)
  File "/Library/Frameworks/Python.framework/Versions/3.7/lib/python3.7/site-packages/flask_login/utils.py", line 272, in decorated_view
    return func(*args, **kwargs)
  File "/Users/steve/Delphi Dropbox/Clients/TwinningProject/Code/ttp/app/decorators.py", line 13, in decorated_function
    return f(*args, **kwargs)
  File "/Users/steve/Delphi Dropbox/Clients/TwinningProject/Code/ttp/app/main/routes.py", line 870, in assignkit
    db.session.commit()
  File "/Library/Frameworks/Python.framework/Versions/3.7/lib/python3.7/site-packages/sqlalchemy/orm/scoping.py", line 162, in do
    return getattr(self.registry(), name)(*args, **kwargs)
  File "/Library/Frameworks/Python.framework/Versions/3.7/lib/python3.7/site-packages/sqlalchemy/orm/session.py", line 1036, in commit
    self.transaction.commit()
  File "/Library/Frameworks/Python.framework/Versions/3.7/lib/python3.7/site-packages/sqlalchemy/orm/session.py", line 503, in commit
    self._prepare_impl()
  File "/Library/Frameworks/Python.framework/Versions/3.7/lib/python3.7/site-packages/sqlalchemy/orm/session.py", line 482, in _prepare_impl
    self.session.flush()
  File "/Library/Frameworks/Python.framework/Versions/3.7/lib/python3.7/site-packages/sqlalchemy/orm/session.py", line 2496, in flush
    self._flush(objects)
  File "/Library/Frameworks/Python.framework/Versions/3.7/lib/python3.7/site-packages/sqlalchemy/orm/session.py", line 2637, in _flush
    transaction.rollback(_capture_exception=True)
  File "/Library/Frameworks/Python.framework/Versions/3.7/lib/python3.7/site-packages/sqlalchemy/util/langhelpers.py", line 69, in __exit__
    exc_value, with_traceback=exc_tb,
  File "/Library/Frameworks/Python.framework/Versions/3.7/lib/python3.7/site-packages/sqlalchemy/util/compat.py", line 178, in raise_
    raise exception
  File "/Library/Frameworks/Python.framework/Versions/3.7/lib/python3.7/site-packages/sqlalchemy/orm/session.py", line 2597, in _flush
    flush_context.execute()
  File "/Library/Frameworks/Python.framework/Versions/3.7/lib/python3.7/site-packages/sqlalchemy/orm/unitofwork.py", line 422, in execute
    rec.execute(self)
  File "/Library/Frameworks/Python.framework/Versions/3.7/lib/python3.7/site-packages/sqlalchemy/orm/unitofwork.py", line 589, in execute
    uow,
  File "/Library/Frameworks/Python.framework/Versions/3.7/lib/python3.7/site-packages/sqlalchemy/orm/persistence.py", line 245, in save_obj
    insert,
  File "/Library/Frameworks/Python.framework/Versions/3.7/lib/python3.7/site-packages/sqlalchemy/orm/persistence.py", line 1136, in _emit_insert_statements
    statement, params
  File "/Library/Frameworks/Python.framework/Versions/3.7/lib/python3.7/site-packages/sqlalchemy/engine/base.py", line 984, in execute
    return meth(self, multiparams, params)
  File "/Library/Frameworks/Python.framework/Versions/3.7/lib/python3.7/site-packages/sqlalchemy/sql/elements.py", line 293, in _execute_on_connection
    return connection._execute_clauseelement(self, multiparams, params)
  File "/Library/Frameworks/Python.framework/Versions/3.7/lib/python3.7/site-packages/sqlalchemy/engine/base.py", line 1103, in _execute_clauseelement
    distilled_params,
  File "/Library/Frameworks/Python.framework/Versions/3.7/lib/python3.7/site-packages/sqlalchemy/engine/base.py", line 1178, in _execute_context
    e, util.text_type(statement), parameters, None, None
  File "/Library/Frameworks/Python.framework/Versions/3.7/lib/python3.7/site-packages/sqlalchemy/engine/base.py", line 1482, in _handle_dbapi_exception
    sqlalchemy_exception, with_traceback=exc_info[2], from_=e
  File "/Library/Frameworks/Python.framework/Versions/3.7/lib/python3.7/site-packages/sqlalchemy/util/compat.py", line 178, in raise_
    raise exception
  File "/Library/Frameworks/Python.framework/Versions/3.7/lib/python3.7/site-packages/sqlalchemy/engine/base.py", line 1175, in _execute_context
    context = constructor(dialect, self, conn, *args)
  File "/Library/Frameworks/Python.framework/Versions/3.7/lib/python3.7/site-packages/sqlalchemy/engine/default.py", line 836, in _init_compiled
    param.append(processors[key](compiled_params[key]))
  File "/Library/Frameworks/Python.framework/Versions/3.7/lib/python3.7/site-packages/sqlalchemy/dialects/sqlite/base.py", line 768, in process
    "SQLite DateTime type only accepts Python "
sqlalchemy.exc.StatementError: (builtins.TypeError) SQLite DateTime type only accepts Python datetime and date objects as input.
[SQL: INSERT INTO kit_order (order_cohortid, order_time) VALUES (?, ?)]
[parameters: [{'order_time': <built-in method utcnow of type object at 0x10a602648>, 'order_cohortid': '11'}]]
2021-11-17 11:44:58,093 INFO: The Twinning Project [in /Users/steve/Delphi Dropbox/Clients/TwinningProject/Code/ttp/app/__init__.py: 86]
2021-11-17 14:10:16,763 INFO: The Twinning Project [in /Users/steve/Delphi Dropbox/Clients/TwinningProject/Code/ttp/app/__init__.py: 86]
2021-11-17 14:12:36,446 INFO: The Twinning Project [in /Users/steve/Delphi Dropbox/Clients/TwinningProject/Code/ttp/app/__init__.py: 86]
2021-11-17 14:25:55,456 INFO: The Twinning Project [in /Users/steve/Delphi Dropbox/Clients/TwinningProject/Code/ttp/app/__init__.py: 86]
2021-11-17 14:28:14,491 ERROR: Exception on /assignkit/11 [POST] [in /Library/Frameworks/Python.framework/Versions/3.7/lib/python3.7/site-packages/flask/app.py: 1892]
Traceback (most recent call last):
  File "/Library/Frameworks/Python.framework/Versions/3.7/lib/python3.7/site-packages/flask/app.py", line 2447, in wsgi_app
    response = self.full_dispatch_request()
  File "/Library/Frameworks/Python.framework/Versions/3.7/lib/python3.7/site-packages/flask/app.py", line 1952, in full_dispatch_request
    rv = self.handle_user_exception(e)
  File "/Library/Frameworks/Python.framework/Versions/3.7/lib/python3.7/site-packages/flask/app.py", line 1821, in handle_user_exception
    reraise(exc_type, exc_value, tb)
  File "/Library/Frameworks/Python.framework/Versions/3.7/lib/python3.7/site-packages/flask/_compat.py", line 39, in reraise
    raise value
  File "/Library/Frameworks/Python.framework/Versions/3.7/lib/python3.7/site-packages/flask/app.py", line 1950, in full_dispatch_request
    rv = self.dispatch_request()
  File "/Library/Frameworks/Python.framework/Versions/3.7/lib/python3.7/site-packages/flask/app.py", line 1936, in dispatch_request
    return self.view_functions[rule.endpoint](**req.view_args)
  File "/Library/Frameworks/Python.framework/Versions/3.7/lib/python3.7/site-packages/flask_login/utils.py", line 272, in decorated_view
    return func(*args, **kwargs)
  File "/Users/steve/Delphi Dropbox/Clients/TwinningProject/Code/ttp/app/decorators.py", line 13, in decorated_function
    return f(*args, **kwargs)
  File "/Users/steve/Delphi Dropbox/Clients/TwinningProject/Code/ttp/app/main/routes.py", line 894, in assignkit
    stock_item.qty = stock_item.qty - item_qty
AttributeError: 'BaseQuery' object has no attribute 'qty'
2021-11-17 14:36:19,302 INFO: The Twinning Project [in /Users/steve/Delphi Dropbox/Clients/TwinningProject/Code/ttp/app/__init__.py: 86]
