2020-05-27 15:02:48,894 ERROR: Exception on /edit_cohort/5 [GET] [in /Users/steve/Delphi Dropbox/Clients/TwinningProject/Code/TTP/venv/lib/python3.7/site-packages/flask/app.py: 1892]
Traceback (most recent call last):
  File "/Users/steve/Delphi Dropbox/Clients/TwinningProject/Code/TTP/venv/lib/python3.7/site-packages/flask/app.py", line 2447, in wsgi_app
    response = self.full_dispatch_request()
  File "/Users/steve/Delphi Dropbox/Clients/TwinningProject/Code/TTP/venv/lib/python3.7/site-packages/flask/app.py", line 1952, in full_dispatch_request
    rv = self.handle_user_exception(e)
  File "/Users/steve/Delphi Dropbox/Clients/TwinningProject/Code/TTP/venv/lib/python3.7/site-packages/flask/app.py", line 1821, in handle_user_exception
    reraise(exc_type, exc_value, tb)
  File "/Users/steve/Delphi Dropbox/Clients/TwinningProject/Code/TTP/venv/lib/python3.7/site-packages/flask/_compat.py", line 39, in reraise
    raise value
  File "/Users/steve/Delphi Dropbox/Clients/TwinningProject/Code/TTP/venv/lib/python3.7/site-packages/flask/app.py", line 1950, in full_dispatch_request
    rv = self.dispatch_request()
  File "/Users/steve/Delphi Dropbox/Clients/TwinningProject/Code/TTP/venv/lib/python3.7/site-packages/flask/app.py", line 1936, in dispatch_request
    return self.view_functions[rule.endpoint](**req.view_args)
  File "/Users/steve/Delphi Dropbox/Clients/TwinningProject/Code/TTP/venv/lib/python3.7/site-packages/flask_login/utils.py", line 272, in decorated_view
    return func(*args, **kwargs)
  File "/Users/steve/Delphi Dropbox/Clients/TwinningProject/Code/TTP/app/main/routes.py", line 104, in edit_cohort
    form.coh_prison.data = cohort.prs_cohort.name
AttributeError: 'Prison' object has no attribute 'name'
2020-05-27 15:03:11,053 INFO: The Twinning Project [in /Users/steve/Delphi Dropbox/Clients/TwinningProject/Code/TTP/app/__init__.py: 71]
2020-05-27 15:03:34,272 ERROR: Exception on /edit_cohort/5 [POST] [in /Users/steve/Delphi Dropbox/Clients/TwinningProject/Code/TTP/venv/lib/python3.7/site-packages/flask/app.py: 1892]
Traceback (most recent call last):
  File "/Users/steve/Delphi Dropbox/Clients/TwinningProject/Code/TTP/venv/lib/python3.7/site-packages/sqlalchemy/engine/base.py", line 1175, in _execute_context
    context = constructor(dialect, self, conn, *args)
  File "/Users/steve/Delphi Dropbox/Clients/TwinningProject/Code/TTP/venv/lib/python3.7/site-packages/sqlalchemy/engine/default.py", line 836, in _init_compiled
    param.append(processors[key](compiled_params[key]))
  File "/Users/steve/Delphi Dropbox/Clients/TwinningProject/Code/TTP/venv/lib/python3.7/site-packages/sqlalchemy/dialects/sqlite/base.py", line 768, in process
    "SQLite DateTime type only accepts Python "
TypeError: SQLite DateTime type only accepts Python datetime and date objects as input.

The above exception was the direct cause of the following exception:

Traceback (most recent call last):
  File "/Users/steve/Delphi Dropbox/Clients/TwinningProject/Code/TTP/venv/lib/python3.7/site-packages/flask/app.py", line 2447, in wsgi_app
    response = self.full_dispatch_request()
  File "/Users/steve/Delphi Dropbox/Clients/TwinningProject/Code/TTP/venv/lib/python3.7/site-packages/flask/app.py", line 1952, in full_dispatch_request
    rv = self.handle_user_exception(e)
  File "/Users/steve/Delphi Dropbox/Clients/TwinningProject/Code/TTP/venv/lib/python3.7/site-packages/flask/app.py", line 1821, in handle_user_exception
    reraise(exc_type, exc_value, tb)
  File "/Users/steve/Delphi Dropbox/Clients/TwinningProject/Code/TTP/venv/lib/python3.7/site-packages/flask/_compat.py", line 39, in reraise
    raise value
  File "/Users/steve/Delphi Dropbox/Clients/TwinningProject/Code/TTP/venv/lib/python3.7/site-packages/flask/app.py", line 1950, in full_dispatch_request
    rv = self.dispatch_request()
  File "/Users/steve/Delphi Dropbox/Clients/TwinningProject/Code/TTP/venv/lib/python3.7/site-packages/flask/app.py", line 1936, in dispatch_request
    return self.view_functions[rule.endpoint](**req.view_args)
  File "/Users/steve/Delphi Dropbox/Clients/TwinningProject/Code/TTP/venv/lib/python3.7/site-packages/flask_login/utils.py", line 272, in decorated_view
    return func(*args, **kwargs)
  File "/Users/steve/Delphi Dropbox/Clients/TwinningProject/Code/TTP/app/main/routes.py", line 99, in edit_cohort
    db.session.commit()
  File "/Users/steve/Delphi Dropbox/Clients/TwinningProject/Code/TTP/venv/lib/python3.7/site-packages/sqlalchemy/orm/scoping.py", line 162, in do
    return getattr(self.registry(), name)(*args, **kwargs)
  File "/Users/steve/Delphi Dropbox/Clients/TwinningProject/Code/TTP/venv/lib/python3.7/site-packages/sqlalchemy/orm/session.py", line 1036, in commit
    self.transaction.commit()
  File "/Users/steve/Delphi Dropbox/Clients/TwinningProject/Code/TTP/venv/lib/python3.7/site-packages/sqlalchemy/orm/session.py", line 503, in commit
    self._prepare_impl()
  File "/Users/steve/Delphi Dropbox/Clients/TwinningProject/Code/TTP/venv/lib/python3.7/site-packages/sqlalchemy/orm/session.py", line 482, in _prepare_impl
    self.session.flush()
  File "/Users/steve/Delphi Dropbox/Clients/TwinningProject/Code/TTP/venv/lib/python3.7/site-packages/sqlalchemy/orm/session.py", line 2496, in flush
    self._flush(objects)
  File "/Users/steve/Delphi Dropbox/Clients/TwinningProject/Code/TTP/venv/lib/python3.7/site-packages/sqlalchemy/orm/session.py", line 2637, in _flush
    transaction.rollback(_capture_exception=True)
  File "/Users/steve/Delphi Dropbox/Clients/TwinningProject/Code/TTP/venv/lib/python3.7/site-packages/sqlalchemy/util/langhelpers.py", line 69, in __exit__
    exc_value, with_traceback=exc_tb,
  File "/Users/steve/Delphi Dropbox/Clients/TwinningProject/Code/TTP/venv/lib/python3.7/site-packages/sqlalchemy/util/compat.py", line 178, in raise_
    raise exception
  File "/Users/steve/Delphi Dropbox/Clients/TwinningProject/Code/TTP/venv/lib/python3.7/site-packages/sqlalchemy/orm/session.py", line 2597, in _flush
    flush_context.execute()
  File "/Users/steve/Delphi Dropbox/Clients/TwinningProject/Code/TTP/venv/lib/python3.7/site-packages/sqlalchemy/orm/unitofwork.py", line 422, in execute
    rec.execute(self)
  File "/Users/steve/Delphi Dropbox/Clients/TwinningProject/Code/TTP/venv/lib/python3.7/site-packages/sqlalchemy/orm/unitofwork.py", line 589, in execute
    uow,
  File "/Users/steve/Delphi Dropbox/Clients/TwinningProject/Code/TTP/venv/lib/python3.7/site-packages/sqlalchemy/orm/persistence.py", line 245, in save_obj
    insert,
  File "/Users/steve/Delphi Dropbox/Clients/TwinningProject/Code/TTP/venv/lib/python3.7/site-packages/sqlalchemy/orm/persistence.py", line 1136, in _emit_insert_statements
    statement, params
  File "/Users/steve/Delphi Dropbox/Clients/TwinningProject/Code/TTP/venv/lib/python3.7/site-packages/sqlalchemy/engine/base.py", line 984, in execute
    return meth(self, multiparams, params)
  File "/Users/steve/Delphi Dropbox/Clients/TwinningProject/Code/TTP/venv/lib/python3.7/site-packages/sqlalchemy/sql/elements.py", line 293, in _execute_on_connection
    return connection._execute_clauseelement(self, multiparams, params)
  File "/Users/steve/Delphi Dropbox/Clients/TwinningProject/Code/TTP/venv/lib/python3.7/site-packages/sqlalchemy/engine/base.py", line 1103, in _execute_clauseelement
    distilled_params,
  File "/Users/steve/Delphi Dropbox/Clients/TwinningProject/Code/TTP/venv/lib/python3.7/site-packages/sqlalchemy/engine/base.py", line 1178, in _execute_context
    e, util.text_type(statement), parameters, None, None
  File "/Users/steve/Delphi Dropbox/Clients/TwinningProject/Code/TTP/venv/lib/python3.7/site-packages/sqlalchemy/engine/base.py", line 1482, in _handle_dbapi_exception
    sqlalchemy_exception, with_traceback=exc_info[2], from_=e
  File "/Users/steve/Delphi Dropbox/Clients/TwinningProject/Code/TTP/venv/lib/python3.7/site-packages/sqlalchemy/util/compat.py", line 178, in raise_
    raise exception
  File "/Users/steve/Delphi Dropbox/Clients/TwinningProject/Code/TTP/venv/lib/python3.7/site-packages/sqlalchemy/engine/base.py", line 1175, in _execute_context
    context = constructor(dialect, self, conn, *args)
  File "/Users/steve/Delphi Dropbox/Clients/TwinningProject/Code/TTP/venv/lib/python3.7/site-packages/sqlalchemy/engine/default.py", line 836, in _init_compiled
    param.append(processors[key](compiled_params[key]))
  File "/Users/steve/Delphi Dropbox/Clients/TwinningProject/Code/TTP/venv/lib/python3.7/site-packages/sqlalchemy/dialects/sqlite/base.py", line 768, in process
    "SQLite DateTime type only accepts Python "
sqlalchemy.exc.StatementError: (builtins.TypeError) SQLite DateTime type only accepts Python datetime and date objects as input.
[SQL: INSERT INTO cohort (coh_desc, coh_clubid, coh_prisonid, "coh_startDate", "coh_endDate", "coh_deliveryDate", coh_tpi) VALUES (?, ?, ?, ?, ?, ?, ?)]
[parameters: [{'coh_prisonid': 'Guys Marsh', 'coh_desc': 'Test', 'coh_clubid': 'Everton', 'coh_startDate': datetime.date(2020, 5, 22), 'coh_tpi': True, 'coh_endDate': <wtforms.fields.core.DateField object at 0x104496e90>, 'coh_deliveryDate': None}]]
